Workbook

Sheet KEY
A1: Category | B1: Common Name | C1: Scientific Name | D1: Native/Nonnative | E1: Federal Listing Status | F1: State Listing Status | G1: Notes
A2: INVERTEBRATES
A3: Spiders | B3: Sheet weaver spider | C3: "Agyneta" #1 | D3: native
A4: Spiders | B4: Sheet weaver spider | C4: "Agyneta" #2 | D4: native
A5: Spiders | B5: Sheet weaver spider | C5: "Disembolus" #1 | D5: native
A6: Spiders | B6: Sheet weaver spider | C6: "Disembolus" #2 | D6: native
A7: Spiders | B7: Sheet weaver spider | C7: "Disembolus" #3 | D7: native
A8: Spiders | B8: Sac spider | C8: Agroeca trivittata | D8: native
A9: Spiders | B9: Wolf spider | C9: Allocosa subparva | D9: native
A10: Spiders | B10: Wolf spider | C10: Alopecosa kochii | D10: native
A11: Spiders | B11: Ghost spider | C11: Anyphaena pacifica | D11: native
A12: Spiders | B12: San Bernadino hills trapdoor spider | C12: Aptostichus atomarius | D12: native
A13: Spiders | B13: Jumping spider | C13: Attinella dorsata | D13: native
A14: Spiders | B14: California Trapdoor spider | C14: Bothriocyrtum californicum | D14: native
... A75: Beetles | B75: Little Bear | C75: Paracotalpa ursina | D75: unsure
A76: Beetles | B76: Minute Brown Scavenger Beetle | C76: Revelieria california | D76: unsure | E76: edar
A77: Beetles | B77: Pea and Bean Weevil | C77: Stator limbatus | D77: unsure
A78: Beetles | B78: Tule Beetle | C78: Tanystoma maculicolle | D78: unsure
A79: Beetles | B79: Bark and Ambrosia Beetle | C79: Xyleborinus sp. | D79: unsure
A80: Flies | B80: Small Fruit Fly | C80: Drosophila repleta | D80: unsure
A81: Ants, Bees, Wasps | B81: Fine Striped Sweat Bee | C81: Agapostemon subtilior | D81: native
A82: Ants, Bees, Wasps | B82: European honey bee | C82: Apis mellifera | D82: non-native
A83: Ants, Bees, Wasps | B83: Yellow-faced Bumble Bee | C83: Bombus vosnesenskii | D83: native
A84: Ants, Bees, Wasps | B84: Arizona Small Carpenter | C84: Ceratina arizonensis | D84: unsure
A85: Ants, Bees, Wasps | B85: Cactus Chimney Bee | C85: Diadasia australis | D85: native
A86: Ants, Bees, Wasps | B86: Bindweed Turret Bee | C86: Diadasia bituberculata | D86: native
A87: Ants, Bees, Wasps | B87: White-haired Monk Longhorn | C87: Eucera frater albopilosa | D87: unsure
A88: Ants, Bees, Wasps | B88: Digger Bee | C88: Habropoda tristissima | D88: unsure
... A100: Arachnid | B100: Short-tailed whip scorpion | C100: Hubbardia pentapeltis | D100: native
A101: REPTILES & AMPHIBIANS
A102: Lizards | B102: Southern California Legless Lizard | C102: Anniella stebbinsi | D102: native | F102: CDFW: Species of Special Concern
A103: Salamanders | B103: Arboreal Salamander | C103: Aneides lugubris | D103: native
A104: Frogs | B104: Western Toad | C104: Anaxyrus boreas | D104: native
A105: Lizards | B105: Orange-throated Whiptail | C105: Aspidoscelis hyperythrus | D105: native | F105: CDFW: Species of Special Concern (Watch List)
A106: Lizards | B106: Tiger Whiptail | C106: Aspidoscelis tigris | D106: native | F106: CDFW: Species of Special Concern
A107: Salamanders | B107: Garden Slender Salamander | C107: Batrachoseps major | D107: native
A108: Snakes | B108: North American Racer | C108: Coluber constrictor | D108: native
A109: Snakes | B109: Western Rattlesnake | C109: Crotalus oreganus | D109: native
A110: Snakes | B110: Red Diamond Rattlesnake | C110: Crotalus ruber | D110: native | F110: CDFW: Species of Special Concern
A111: Snakes | B111: Rattlesnake | C111: Crotalus sp. | D111: native
...

Sheet 32nd_GoldenHill
A1: Canyon | B1: Group | C1: Category | D1: Common Name | E1: Scientific Name | F1: Status | G1: Federal Listing Status | H1: State Listing Status | I1: iNat observation only
B2: INVERTEBRATES
A3: 32nd/Golden Hill | B3: INVERTEBRATES | C3: Ants, Bees, Wasps | D3: Argentine Ant | E3: Linepithema humile | F3: non-native | G3: 0 | H3: 0
A4: 32nd/Golden Hill | B4: INVERTEBRATES | C4: Spiders | D4: Ground spider | E4: Drassyllus insularis | F4: native | G4: 0 | H4: 0
A5: 32nd/Golden Hill | B5: INVERTEBRATES | C5: Arachnid | D5: Opiliones | E5: Protolophus singularis | F5: native | G5: 0 | H5: 0
A6: 32nd/Golden Hill | B6: INVERTEBRATES | C6: Spiders | D6: Jumping spider | E6: Attinella dorsata | F6: native | G6: 0 | H6: 0
A7: 32nd/Golden Hill | B7: INVERTEBRATES | C7: Spiders | D7: Wolf spider | E7: Alopecosa kochii | F7: native | G7: 0 | H7: 0
A8: 32nd/Golden Hill | B8: INVERTEBRATES | C8: Spiders | D8: Prowling spider | E8: Syspira tigrina | F8: native | G8: 0 | H8: 0
A9: 32nd/Golden Hill | B9: INVERTEBRATES | C9: Ants, Bees, Wasps | D9: European honey bee | E9: Apis mellifera | F9: non-native | G9: 0 | H9: 0
A10: 32nd/Golden Hill | B10: INVERTEBRATES | C10: Beetles | D10: Soft-winged Flower Beetle | E10: Eschatocrepis constrictus | F10: unsure | G10: 0 | H10: 0
A11: 32nd/Golden Hill | B11: INVERTEBRATES | C11: Ants, Bees, Wasps | D11: Tripartite Sweat Bee | E11: Halictus tripartitus | F11: non-native | G11: 0 | H11: 0
A12: 32nd/Golden Hill | B12: INVERTEBRATES | C12: Spiders | D12: Crab spider | E12: Xysticus californicus | F12: native | G12: 0 | H12: 0
A13: 32nd/Golden Hill | B13: INVERTEBRATES | C13: Spiders | D13: Sheet weaver spider | E13: "Disembolus" #3 | F13: native | G13: 0 | H13: 0
A14: 32nd/Golden Hill | B14: INVERTEBRATES | C14: Spiders | D14: Wall spider | E14: Oecobius navus | F14: non-native | G14: 0 | H14: 0
... A18: 32nd/Golden Hill | B18: INVERTEBRATES | C18: Spiders | D18: South American toothed hacklemesh weaver spider | E18: Metaltella simoni | F18: non-native | G18: 0 | H18: 0
B19: REPTILES & AMPHIBIANS
A20: 32nd/Golden Hill | B20: REPTILES & AMPHIBIANS | C20: Lizards | D20: Southern California Legless Lizard | E20: Anniella stebbinsi | F20: native | G20: 0 | H20: CDFW: Species of Special Concern
A21: 32nd/Golden Hill | B21: REPTILES & AMPHIBIANS | C21: Lizards | D21: Orange-throated Whiptail | E21: Aspidoscelis hyperythrus | F21: native | G21: 0 | H21: CDFW: Species of Special Concern (Watch List)
A22: 32nd/Golden Hill | B22: REPTILES & AMPHIBIANS | C22: Lizards | D22: Southern Alligator Lizard | E22: Elgaria multicarinata | F22: native | G22: 0 | H22: 0
A23: 32nd/Golden Hill | B23: REPTILES & AMPHIBIANS | C23: Snakes | D23: Brahminy Blind Snake | E23: Indotyphlops braminus | F23: non-native | G23: 0 | H23: 0
A24: 32nd/Golden Hill | B24: REPTILES & AMPHIBIANS | C24: Snakes | D24: Gophersnake | E24: Pituophis catenifer | F24: native | G24: 0 | H24: 0
A25: 32nd/Golden Hill | B25: REPTILES & AMPHIBIANS | C25: Lizards | D25: Western Fence Lizard | E25: Sceloporus occidentalis | F25: native | G25: 0 | H25: 0
B26: BIRDS
A27: 32nd/Golden Hill | B27: BIRDS | C27: Hawks & Eagles | D27: Cooper's Hawk | E27: Accipiter cooperii | F27: native | G27: 0 | H27: CDFW: Watch List
A28: 32nd/Golden Hill | B28: BIRDS | C28: Hawks & Eagles | D28: Red-shouldered Hawk | E28: Buteo lineatus | F28: native | G28: 0 | H28: 0
A29: 32nd/Golden Hill | B29: BIRDS | C29: Gulls & Terns | D29: Western Gull | E29: Larus occidentalis | F29: native | G29: 0 | H29: 0
A30: 32nd/Golden Hill | B30: BIRDS | C30: Pigeons & Doves | D30: Domestic Pigeon | E30: Columba livia | F30: non-native | G30: 0 | H30: 0
A31: 32nd/Golden Hill | B31: BIRDS | C31: Pigeons & Doves | D31: Mourning Dove | E31: Zenaida macroura | F31: native | G31: 0 | H31: 0
A32: 32nd/Golden Hill | B32: BIRDS | C32: Hummingbirds | D32: Anna's Hummingbird | E32: Calypte anna | F32: native | G32: 0 | H32: 0
A33: 32nd/Golden Hill | B33: BIRDS | C33: Hummingbirds | D33: Allen's Hummingbird | E33: Selasphorus sasin | F33: native | G33: 0 | H33: 0
A34: 32nd/Golden Hill | B34: BIRDS | C34: Woodpeckers | D34: Nuttall's Woodpecker | E34: Dryobates nuttallii | F34: native | G34: 0 | H34: 0
A35: 32nd/Golden Hill | B35: BIRDS | C35: Tyrant Flycatchers | D35: Western Flycatcher | E35: Empidonax difficilis | F35: native | G35: 0 | H35: 0
A36: 32nd/Golden Hill | B36: BIRDS | C36: Tyrant Flycatchers | D36: Black Phoebe | E36: Sayornis nigricans | F36: native | G36: 0 | H36: 0
A37: 32nd/Golden Hill | B37: BIRDS | C37: Tyrant Flycatchers | D37: Cassin's Kingbird | E37: Tyrannus vociferans | F37: native | G37: 0 | H37: 0
A38: 32nd/Golden Hill | B38: BIRDS | C38: Vireos | D38: Hutton's Vireo | E38: Vireo huttoni | F38: native | G38: 0 | H38: 0
A39: 32nd/Golden Hill | B39: BIRDS | C39: Crows & Jays | D39: California Scrub Jay | E39: Aphelocoma californica | F39: native | G39: 0 | H39: 0
... A46: 32nd/Golden Hill | B46: BIRDS | C46: Wrens | D46: House Wren | E46: Troglodytes aedon | F46: native | G46: 0 | H46: 0
A47: 32nd/Golden Hill | B47: BIRDS | C47: Gnatcatchers | D47: California Gnatcatcher | E47: Polioptila californica californica | F47: native | G47: Federally Threatened | H47: CDFW: Species of Special Concern
A48: 32nd/Golden Hill | B48: BIRDS | C48: Bushtits | D48: Bushtit | E48: Psaltriparus minimus | F48: native | G48: 0 | H48: 0
A49: 32nd/Golden Hill | B49: BIRDS | C49: Kinglets | D49: Ruby-crowned Kinglet | E49: Regulus calendula | F49: native | G49: 0 | H49: 0
...

Sheet 34th_Juniper
A1: Canyon | B1: Group | C1: Category | D1: Common Name | E1: Scientific Name | F1: Status | G1: Federal Listing Status | H1: State Listing Status | I1: iNat observation only
B2: INVERTEBRATES
A3: Juniper South | B3: INVERTEBRATES | C3: Spiders | D3: Wall spider | E3: Oecobius navus | F3: non-native | G3: 0 | H3: 0
A4: Juniper South | B4: INVERTEBRATES | C4: Ants, Bees, Wasps | D4: Argentine Ant | E4: Linepithema humile | F4: non-native | G4: 0 | H4: 0
A5: Juniper South | B5: INVERTEBRATES | C5: Arachnid | D5: Opiliones | E5: Protolophus singularis | F5: native | G5: 0 | H5: 0
A6: Juniper South | B6: INVERTEBRATES | C6: Beetles | D6: Tule Beetle | E6: Tanystoma maculicolle | F6: unsure | G6: 0 | H6: 0
A7: Juniper South | B7: INVERTEBRATES | C7: Ants, Bees, Wasps | D7: Tripartite Sweat Bee | E7: Halictus tripartitus | F7: non-native | G7: 0 | H7: 0
A8: Juniper South | B8: INVERTEBRATES | C8: Beetles | D8: Soft-winged Flower Beetle | E8: Eschatocrepis constrictus | F8: unsure | G8: 0 | H8: 0
A9: Juniper South | B9: INVERTEBRATES | C9: Ants, Bees, Wasps | D9: European honey bee | E9: Apis mellifera | F9: non-native | G9: 0 | H9: 0
A10: Juniper South | B10: INVERTEBRATES | C10: Ants, Bees, Wasps | D10: Fine Striped Sweat Bee | E10: Agapostemon subtilior | F10: native | G10: 0 | H10: 0
A11: * iNat observation only | B11: REPTILES & AMPHIBIANS
A12: Juniper South | B12: REPTILES & AMPHIBIANS | C12: Salamanders | D12: Garden Slender Salamander | E12: Batrachoseps major | F12: native | G12: 0 | H12: 0 | I12: *
A13: Juniper South | B13: REPTILES & AMPHIBIANS | C13: Lizards | D13: Orange-throated Whiptail | E13: Aspidoscelis hyperythrus | F13: native | G13: 0 | H13: CDFW: Species of Special Concern (Watch List)
A14: Juniper South | B14: REPTILES & AMPHIBIANS | C14: Snakes | D14: Ring-necked Snake | E14: Diadophis punctatus | F14: native | G14: 0 | H14: 0 | I14: *
A15: Juniper South | B15: REPTILES & AMPHIBIANS | C15: Lizards | D15: Southern Alligator Lizard | E15: Elgaria multicarinata | F15: native | G15: 0 | H15: 0
A16: Juniper South | B16: REPTILES & AMPHIBIANS | C16: Snakes | D16: Brahminy Blind Snake | E16: Indotyphlops braminus | F16: non-native | G16: 0 | H16: 0
A17: Juniper South | B17: REPTILES & AMPHIBIANS | C17: Snakes | D17: California Kingsnake | E17: Lampropeltis californiae | F17: native | G17: 0 | H17: 0 | I17: *
A18: Juniper South | B18: REPTILES & AMPHIBIANS | C18: Snakes | D18: Gophersnake | E18: Pituophis catenifer | F18: native | G18: 0 | H18: 0 | I18: *
A19: Juniper South | B19: REPTILES & AMPHIBIANS | C19: Lizards | D19: Western Fence Lizard | E19: Sceloporus occidentalis | F19: native | G19: 0 | H19: 0
A20: Juniper South | B20: REPTILES & AMPHIBIANS | C20: Lizards | D20: Common Side-blotched Lizard | E20: Uta stansburiana | F20: native | G20: 0 | H20: 0
B21: BIRDS
A22: Juniper South | B22: BIRDS | C22: Hawks & Eagles | D22: Sharp-shinned Hawk | E22: Accipiter striatus | F22: native | G22: 0 | H22: CDFW: Watch List
A23: Juniper South | B23: BIRDS | C23: Hawks & Eagles | D23: Cooper's Hawk | E23: Accipiter cooperii | F23: native | G23: 0 | H23: CDFW: Watch List
A24: Juniper South | B24: BIRDS | C24: Hawks & Eagles | D24: Red-shouldered Hawk | E24: Buteo lineatus | F24: native | G24: 0 | H24: 0
A25: Juniper South | B25: BIRDS | C25: Gulls & Terns | D25: Western Gull | E25: Larus occidentalis | F25: native | G25: 0 | H25: 0
A26: Juniper South | B26: BIRDS | C26: Pigeons & Doves | D26: Domestic Pigeon | E26: Columba livia | F26: non-native | G26: 0 | H26: 0
A27: Juniper South | B27: BIRDS | C27: Pigeons & Doves | D27: Mourning Dove | E27: Zenaida macroura | F27: native | G27: 0 | H27: 0
A28: Juniper South | B28: BIRDS | C28: Parrot | D28: Red-masked Parakeet | E28: Aratinga erythrogenys | F28: non-native | G28: 0 | H28: 0
A29: Juniper South | B29: BIRDS | C29: Swifts | D29: Vaux's Swift | E29: Chaetura vauxi | F29: native | G29: 0 | H29: CDFW: Species of Special Concern
A30: Juniper South | B30: BIRDS | C30: Swifts | D30: White-throated Swift | E30: Aeronautes saxatalis | F30: native | G30: 0 | H30: 0
A31: Juniper South | B31: BIRDS | C31: Hummingbirds | D31: Anna's Hummingbird | E31: Calypte anna | F31: native | G31: 0 | H31: 0
A32: Juniper South | B32: BIRDS | C32: Hummingbirds | D32: Allen's Hummingbird | E32: Selasphorus sasin | F32: native | G32: 0 | H32: 0
A33: Juniper South | B33: BIRDS | C33: Woodpeckers | D33: Nuttall's Woodpecker | E33: Dryobates nuttallii | F33: native | G33: 0 | H33: 0
A34: Juniper South | B34: BIRDS | C34: Tyrant Flycatchers | D34: Western Flycatcher | E34: Empidonax difficilis | F34: native | G34: 0 | H34: 0
A35: Juniper South | B35: BIRDS | C35: Tyrant Flycatchers | D35: Black Phoebe | E35: Sayornis nigricans | F35: native | G35: 0 | H35: 0
A36: Juniper South | B36: BIRDS | C36: Tyrant Flycatchers | D36: Ash-throated Flycatcher | E36: Myiarchus cinerascens | F36: native | G36: 0 | H36: 0
A37: Juniper South | B37: BIRDS | C37: Tyrant Flycatchers | D37: Cassin's Kingbird | E37: Tyrannus vociferans | F37: native | G37: 0 | H37: 0
A38: Juniper South | B38: BIRDS | C38: Crows & Jays | D38: California Scrub Jay | E38: Aphelocoma californica | F38: native | G38: 0 | H38: 0
A39: Juniper South | B39: BIRDS | C39: Crows & Jays | D39: American Crow | E39: Corvus brachyrhynchos | F39: native | G39: 0 | H39: 0
A40: Juniper South | B40: BIRDS | C40: Crows & Jays | D40: Common Raven | E40: Corvus corax | F40: native | G40: 0 | H40: 0
...

Sheet 47th_Olivia
A1: Canyon | B1: Group | C1: Category | D1: Common Name | E1: Scientific Name | F1: Status | G1: Federal Listing Status | H1: State Listing Status
B2: INVERTEBRATES
A3: Olivia | B3: INVERTEBRATES | C3: Spiders | D3: Wolf spider | E3: Schizocosa mccooki | F3: native | G3: 0 | H3: 0
A4: Olivia | B4: INVERTEBRATES | C4: Ants, Bees, Wasps | D4: Argentine Ant | E4: Linepithema humile | F4: non-native | G4: 0 | H4: 0
A5: Olivia | B5: INVERTEBRATES | C5: Spiders | D5: Wandering spider | E5: Socalchemmis miramar | F5: native | G5: 0 | H5: 0
A6: Olivia | B6: INVERTEBRATES | C6: Spiders | D6: Woodlouse spider | E6: Dysdera crocata | F6: non-native | G6: 0 | H6: 0
A7: Olivia | B7: INVERTEBRATES | C7: Spiders | D7: South American toothed hacklemesh weaver spider | E7: Metaltella simoni | F7: non-native | G7: 0 | H7: 0
A8: Olivia | B8: INVERTEBRATES | C8: Spiders | D8: Prowling spider | E8: Syspira tigrina | F8: native | G8: 0 | H8: 0
A9: Olivia | B9: INVERTEBRATES | C9: Ants, Bees, Wasps | D9: Fine Striped Sweat Bee | E9: Agapostemon subtilior | F9: native | G9: 0 | H9: 0
A10: Olivia | B10: INVERTEBRATES | C10: Ants, Bees, Wasps | D10: Cactus Chimney Bee | E10: Diadasia australis | F10: native | G10: 0 | H10: 0
A11: Olivia | B11: INVERTEBRATES | C11: Ants, Bees, Wasps | D11: Longhorn Bee | E11: Melissodes tessellatus | F11: unsure | G11: 0 | H11: 0
A12: Olivia | B12: INVERTEBRATES | C12: Ants, Bees, Wasps | D12: Tripartite Sweat Bee | E12: Halictus tripartitus | F12: non-native | G12: 0 | H12: 0
A13: Olivia | B13: INVERTEBRATES | C13: Spiders | D13: Wolf spider | E13: Pardosa californica | F13: native | G13: 0 | H13: 0
A14: Olivia | B14: INVERTEBRATES | C14: Spiders | D14: Wall spider | E14: Oecobius navus | F14: non-native | G14: 0 | H14: 0
... A21: Olivia | B21: INVERTEBRATES | C21: Ants, Bees, Wasps | D21: European honey bee | E21: Apis mellifera | F21: non-native | G21: 0 | H21: 0
B22: REPTILES & AMPHIBIANS | D22: * denotes iNat observation only
A23: Olivia | B23: REPTILES & AMPHIBIANS | C23: Lizards | D23: Orange-throated Whiptail | E23: Aspidoscelis hyperythrus | F23: native | G23: 0 | H23: CDFW: Species of Special Concern (Watch List)
A24: Olivia | B24: REPTILES & AMPHIBIANS | C24: Salamanders | D24: Garden Slender Salamander | E24: Batrachoseps major | F24: native | G24: 0 | H24: 0
A25: Olivia | B25: REPTILES & AMPHIBIANS | C25: Lizards | D25: Southern Alligator Lizard | E25: Elgaria multicarinata | F25: native | G25: 0 | H25: 0
A26: Olivia | B26: REPTILES & AMPHIBIANS | C26: Snakes | D26: Brahminy Blind Snake | E26: Indotyphlops braminus | F26: non-native | G26: 0 | H26: 0
A27: Olivia | B27: REPTILES & AMPHIBIANS | C27: Lizards | D27: Western Fence Lizard | E27: Sceloporus occidentalis | F27: native | G27: 0 | H27: 0
A28: Olivia | B28: REPTILES & AMPHIBIANS | C28: Lizards | D28: Common Side-blotched Lizard | E28: Uta stansburiana | F28: native | G28: 0 | H28: 0
B29: BIRDS | C29: BIRDS
A30: Olivia | B30: BIRDS | C30: Hawks & Eagles | D30: Cooper's Hawk | E30: Accipiter cooperii | F30: native | G30: 0 | H30: CDFW: Watch List
A31: Olivia | B31: BIRDS | C31: Hawks & Eagles | D31: Red-shouldered Hawk | E31: Buteo lineatus | F31: native | G31: 0 | H31: 0
A32: Olivia | B32: BIRDS | C32: Owls | D32: Great Horned Owl | E32: Bubo virginianus | F32: native | G32: 1 | H32: 0 | I32: Camera Trap By-catch
A33: Olivia | B33: BIRDS | C33: Gulls & Terns | D33: Western Gull | E33: Larus occidentalis | F33: native | G33: 0 | H33: 0
A34: Olivia | B34: BIRDS | C34: Pigeons & Doves | D34: Domestic Pigeon | E34: Columba livia | F34: non-native | G34: 0 | H34: 0
A35: Olivia | B35: BIRDS | C35: Pigeons & Doves | D35: Mourning Dove | E35: Zenaida macroura | F35: native | G35: 0 | H35: 0
A36: Olivia | B36: BIRDS | C36: Parrot | D36: Red-masked Parakeet | E36: Aratinga erythrogenys | F36: non-native | G36: 0 | H36: 0
A37: Olivia | B37: BIRDS | C37: Parrots | D37: Red-crowned Parrot | E37: Amazona viridigenalis | F37: non-native | G37: 0 | H37: 0 | I37: Observation: Red/Lilac-crowned Parrot
A38: Olivia | B38: BIRDS | C38: Swifts | D38: Vaux's Swift | E38: Chaetura vauxi | F38: native | G38: 0 | H38: CDFW: Species of Special Concern
A39: Olivia | B39: BIRDS | C39: Hummingbirds | D39: Anna's Hummingbird | E39: Calypte anna | F39: native | G39: 0 | H39: 0
A40: Olivia | B40: BIRDS | C40: Hummingbirds | D40: Allen's Hummingbird | E40: Selasphorus sasin | F40: native | G40: 0 | H40: 0
A41: Olivia | B41: BIRDS | C41: Woodpeckers | D41: Nuttall's Woodpecker | E41: Dryobates nuttallii | F41: native | G41: 0 | H41: 0
A42: Olivia | B42: BIRDS | C42: Tyrant Flycatchers | D42: Western Flycatcher | E42: Empidonax difficilis | F42: native | G42: 0 | H42: 0
A43: Olivia | B43: BIRDS | C43: Tyrant Flycatchers | D43: Black Phoebe | E43: Sayornis nigricans | F43: native | G43: 0 | H43: 0
A44: Olivia | B44: BIRDS | C44: Tyrant Flycatchers | D44: Ash-throated Flycatcher | E44: Myiarchus cinerascens | F44: native | G44: 0 | H44: 0
A45: Olivia | B45: BIRDS | C45: Tyrant Flycatchers | D45: Cassin's Kingbird | E45: Tyrannus vociferans | F45: native | G45: 0 | H45: 0
A46: Olivia | B46: BIRDS | C46: Vireos | D46: Hutton's Vireo | E46: Vireo huttoni | F46: native | G46: 0 | H46: 0
...

Sheet Chollas_EmeraldHills
A1: Canyon | B1: Group | C1: Category | D1: Common Name | E1: Scientific Name | F1: Status | G1: Federal Listing Status | H1: State Listing Status
B2: INVERTEBRATES
A3: Chollas South/Emerald Hills | B3: INVERTEBRATES | C3: Ants, Bees, Wasps | D3: Argentine Ant | E3: Linepithema humile | F3: non-native | G3: 0 | H3: 0
A4: Chollas South/Emerald Hills | B4: INVERTEBRATES | C4: Spiders | D4: Ground spider | E4: Drassyllus insularis | F4: native | G4: 0 | H4: 0
A5: Chollas South/Emerald Hills | B5: INVERTEBRATES | C5: Arachnid | D5: Opiliones | E5: Protolophus singularis | F5: native | G5: 0 | H5: 0
A6: Chollas South/Emerald Hills | B6: INVERTEBRATES | C6: Spiders | D6: Jumping spider | E6: Attinella dorsata | F6: native | G6: 0 | H6: 0
A7: Chollas South/Emerald Hills | B7: INVERTEBRATES | C7: Spiders | D7: Wolf spider | E7: Alopecosa kochii | F7: native | G7: 0 | H7: 0
A8: Chollas South/Emerald Hills | B8: INVERTEBRATES | C8: Spiders | D8: Prowling spider | E8: Syspira tigrina | F8: native | G8: 0 | H8: 0
A9: Chollas South/Emerald Hills | B9: INVERTEBRATES | C9: Ants, Bees, Wasps | D9: European honey bee | E9: Apis mellifera | F9: non-native | G9: 0 | H9: 0
A10: Chollas South/Emerald Hills | B10: INVERTEBRATES | C10: Beetles | D10: Soft-winged Flower Beetle | E10: Eschatocrepis constrictus | F10: unsure | G10: 0 | H10: 0
A11: Chollas South/Emerald Hills | B11: INVERTEBRATES | C11: Ants, Bees, Wasps | D11: Tripartite Sweat Bee | E11: Halictus tripartitus | F11: non-native | G11: 0 | H11: 0
A12: Chollas South/Emerald Hills | B12: INVERTEBRATES | C12: Spiders | D12: Crab spider | E12: Xysticus californicus | F12: native | G12: 0 | H12: 0
A13: Chollas South/Emerald Hills | B13: INVERTEBRATES | C13: Spiders | D13: Sheet weaver spider | E13: "Disembolus" #3 | F13: native | G13: 0 | H13: 0
A14: Chollas South/Emerald Hills | B14: INVERTEBRATES | C14: Spiders | D14: Wall spider | E14: Oecobius navus | F14: non-native | G14: 0 | H14: 0
... A18: Chollas South/Emerald Hills | B18: INVERTEBRATES | C18: Spiders | D18: South American toothed hacklemesh weaver spider | E18: Metaltella simoni | F18: non-native | G18: 0 | H18: 0
B19: REPTILES & AMPHIBIANS
A20: Chollas South/Emerald Hills | B20: REPTILES & AMPHIBIANS | C20: Lizards | D20: Orange-throated Whiptail | E20: Aspidoscelis hyperythrus | F20: native | G20: 0 | H20: CDFW: Species of Special Concern (Watch List)
A21: Chollas South/Emerald Hills | B21: REPTILES & AMPHIBIANS | C21: Lizards | D21: Southern Alligator Lizard | E21: Elgaria multicarinata | F21: native | G21: 0 | H21: 0
A22: Chollas South/Emerald Hills | B22: REPTILES & AMPHIBIANS | C22: Snakes | D22: California Kingsnake | E22: Lampropeltis californiae | F22: native | G22: 0 | H22: 0
A23: Chollas South/Emerald Hills | B23: REPTILES & AMPHIBIANS | C23: Snakes | D23: Gophersnake | E23: Pituophis catenifer | F23: native | G23: 0 | H23: 0
A24: Chollas South/Emerald Hills | B24: REPTILES & AMPHIBIANS | C24: Lizards | D24: Western Fence Lizard | E24: Sceloporus occidentalis | F24: native | G24: 0 | H24: 0
A25: Chollas South/Emerald Hills | B25: REPTILES & AMPHIBIANS | C25: Lizards | D25: Common Side-blotched Lizard | E25: Uta stansburiana | F25: native | G25: 0 | H25: 0
A26: Chollas South/Emerald Hills | B26: REPTILES & AMPHIBIANS | C26: Frogs | D26: African Clawed Frog | E26: Xenopus laevis | F26: non-native | G26: 0 | H26: 0
B27: BIRDS
A28: Chollas South/Emerald Hills | B28: BIRDS | C28: Hawks & Eagles | D28: Red-shouldered Hawk | E28: Buteo lineatus | F28: native | G28: 0 | H28: 0
A29: Chollas South/Emerald Hills | B29: BIRDS | C29: Hawks & Eagles | D29: Red-tailed Hawk | E29: Buteo jamaicensis | F29: native | G29: 0 | H29: 0
A30: Chollas South/Emerald Hills | B30: BIRDS | C30: Gulls & Terns | D30: Western Gull | E30: Larus occidentalis | F30: native | G30: 0 | H30: 0
A31: Chollas South/Emerald Hills | B31: BIRDS | C31: Pigeons & Doves | D31: Mourning Dove | E31: Zenaida macroura | F31: native | G31: 0 | H31: 0
A32: Chollas South/Emerald Hills | B32: BIRDS | C32: Swifts | D32: White-throated Swift | E32: Aeronautes saxatalis | F32: native | G32: 0 | H32: 0
A33: Chollas South/Emerald Hills | B33: BIRDS | C33: Hummingbirds | D33: Anna's Hummingbird | E33: Calypte anna | F33: native | G33: 0 | H33: 0
A34: Chollas South/Emerald Hills | B34: BIRDS | C34: Hummingbirds | D34: Allen's Hummingbird | E34: Selasphorus sasin | F34: native | G34: 0 | H34: 0
A35: Chollas South/Emerald Hills | B35: BIRDS | C35: Woodpeckers | D35: Nuttall's Woodpecker | E35: Dryobates nuttallii | F35: native | G35: 0 | H35: 0
A36: Chollas South/Emerald Hills | B36: BIRDS | C36: Woodpeckers | D36: Northern Flicker | E36: Colaptes auratus | F36: native | G36: 0 | H36: 0
A37: Chollas South/Emerald Hills | B37: BIRDS | C37: Tyrant Flycatchers | D37: Western Flycatcher | E37: Empidonax difficilis | F37: native | G37: 0 | H37: 0
A38: Chollas South/Emerald Hills | B38: BIRDS | C38: Tyrant Flycatchers | D38: Black Phoebe | E38: Sayornis nigricans | F38: native | G38: 0 | H38: 0
A39: Chollas South/Emerald Hills | B39: BIRDS | C39: Tyrant Flycatchers | D39: Cassin's Kingbird | E39: Tyrannus vociferans | F39: native | G39: 0 | H39: 0
... A46: Chollas South/Emerald Hills | B46: BIRDS | C46: Wrens | D46: Bewick's Wren | E46: Thryomanes bewickii | F46: native | G46: 0 | H46: 0
A47: Chollas South/Emerald Hills | B47: BIRDS | C47: Gnatcatchers | D47: California Gnatcatcher | E47: Polioptila californica californica | F47: native | G47: 0 | H47: CDFW: Species of Special Concern
A48: Chollas South/Emerald Hills | B48: BIRDS | C48: Bushtits | D48: Bushtit | E48: Psaltriparus minimus | F48: native | G48: 0 | H48: 0
A49: Chollas South/Emerald Hills | B49: BIRDS | C49: Swallows | D49: Cliff Swallow | E49: Petrochelidon pyrrhonota | F49: native | G49: 0 | H49: 0
...

Sheet Florida_East
A1: Canyon | B1: Group | C1: Category | D1: Common Name | E1: Scientific Name | F1: Status | G1: Federal Listing Status | H1: State Listing Status | I1: iNat observation only
B2: INVERTEBRATES
A3: Florida East | B3: INVERTEBRATES | C3: Ants, Bees, Wasps | D3: Argentine Ant | E3: Linepithema humile | F3: non-native | G3: 0 | H3: 0
A4: Florida East | B4: INVERTEBRATES | C4: Spiders | D4: Wolf spider | E4: Alopecosa kochii | F4: native | G4: 0 | H4: 0
A5: Florida East | B5: INVERTEBRATES | C5: Ants, Bees, Wasps | D5: Tripartite Sweat Bee | E5: Halictus tripartitus | F5: non-native | G5: 0 | H5: 0
A6: Florida East | B6: INVERTEBRATES | C6: Spiders | D6: Ant mimic spider | E6: Castianeira thalia | F6: native | G6: 0 | H6: 0
A7: Florida East | B7: INVERTEBRATES | C7: Spiders | D7: Paradise spider | E7: Habronattus californicus | F7: native | G7: 0 | H7: 0
A8: Florida East | B8: INVERTEBRATES | C8: Beetles | D8: Soft-winged Flower Beetle | E8: Eschatocrepis constrictus | F8: unsure | G8: 0 | H8: 0
A9: Florida East | B9: INVERTEBRATES | C9: Ants, Bees, Wasps | D9: Yellow-faced Bumble Bee | E9: Bombus vosnesenskii | F9: native | G9: 0 | H9: 0
A10: Florida East | B10: INVERTEBRATES | C10: Ants, Bees, Wasps | D10: European honey bee | E10: Apis mellifera | F10: non-native | G10: 0 | H10: 0
A11: Florida East | B11: INVERTEBRATES | C11: Arachnid | D11: Opiliones | E11: Protolophus singularis | F11: native | G11: 0 | H11: 0
A12: Florida East | B12: INVERTEBRATES | C12: Spiders | D12: Jumping spider | E12: Talavera minuta | F12: native | G12: 0 | H12: 0
A13: Florida East | B13: INVERTEBRATES | C13: Flies | D13: Small Fruit Fly | E13: Drosophila repleta | F13: unsure | G13: 0 | H13: 0
A14: Florida East | B14: INVERTEBRATES | C14: Beetles | D14: California Pink Glowworm | E14: Microphotus angustus | F14: native | G14: 0 | H14: 0
... A25: Florida East | B25: INVERTEBRATES | C25: Spiders | D25: Wall spider | E25: Oecobius navus | F25: non-native | G25: 0 | H25: 0
B26: REPTILES & AMPHIIANS | C26: * iNat observation only
A27: Florida East | B27: REPTILES & AMPHIBIANS | C27: Frogs | D27: Western Toad | E27: Anaxyrus boreas | F27: native | G27: 0 | H27: 0 | I27: *
A28: Florida East | B28: REPTILES & AMPHIBIANS | C28: Lizards | D28: Orange-throated Whiptail | E28: Aspidoscelis hyperythrus | F28: native | G28: 0 | H28: CDFW: Species of Special Concern (Watch List)
A29: Florida East | B29: REPTILES & AMPHIBIANS | C29: Lizards | D29: Southern Alligator Lizard | E29: Elgaria multicarinata | F29: native | G29: 0 | H29: 0
A30: Florida East | B30: REPTILES & AMPHIBIANS | C30: Snakes | D30: Striped Racer | E30: Masticophis lateralis | F30: native | G30: 0 | H30: 0
A31: Florida East | B31: REPTILES & AMPHIBIANS | C31: Snakes | D31: Gophersnake | E31: Pituophis catenifer | F31: native | G31: 0 | H31: 0
A32: Florida East | B32: REPTILES & AMPHIBIANS | C32: Lizards | D32: Western Fence Lizard | E32: Sceloporus occidentalis | F32: native | G32: 0 | H32: 0
A33: Florida East | B33: REPTILES & AMPHIBIANS | C33: Lizards | D33: Common Side-blotched Lizard | E33: Uta stansburiana | F33: native | G33: 0 | H33: 0
A34: Florida East | B34: REPTILES & AMPHIBIANS | C34: Frogs | D34: African Clawed Frog | E34: Xenopus laevis | F34: non-native | G34: 0 | H34: 0 | I34: *
B35: BIRDS
A36: Florida East | B36: BIRDS | C36: Hawks & Eagles | D36: Cooper's Hawk | E36: Accipiter cooperii | F36: native | G36: 0 | H36: CDFW: Watch List
A37: Florida East | B37: BIRDS | C37: Hawks & Eagles | D37: Red-shouldered Hawk | E37: Buteo lineatus | F37: native | G37: 0 | H37: 0
A38: Florida East | B38: BIRDS | C38: Hawks & Eagles | D38: Red-tailed Hawk | E38: Buteo jamaicensis | F38: native | G38: 0 | H38: 0
A39: Florida East | B39: BIRDS | C39: Falcons | D39: American Kestrel | E39: Falco sparverius | F39: native | G39: 0 | H39: 0
A40: Florida East | B40: BIRDS | C40: Gulls & Terns | D40: Western Gull | E40: Larus occidentalis | F40: native | G40: 0 | H40: 0
A41: Florida East | B41: BIRDS | C41: Pigeons & Doves | D41: Mourning Dove | E41: Zenaida macroura | F41: native | G41: 0 | H41: 0
A42: Florida East | B42: BIRDS | C42: Parrots | D42: Red-crowned Parrot | E42: Amazona viridigenalis | F42: non-native | G42: 0 | H42: 0
A43: Florida East | B43: BIRDS | C43: Swifts | D43: White-throated Swift | E43: Aeronautes saxatalis | F43: native | G43: 0 | H43: 0
A44: Florida East | B44: BIRDS | C44: Hummingbirds | D44: Anna's Hummingbird | E44: Calypte anna | F44: native | G44: 0 | H44: 0
A45: Florida East | B45: BIRDS | C45: Hummingbirds | D45: Allen's Hummingbird | E45: Selasphorus sasin | F45: native | G45: 0 | H45: 0
A46: Florida East | B46: BIRDS | C46: Woodpeckers | D46: Nuttall's Woodpecker | E46: Dryobates nuttallii | F46: native | G46: 0 | H46: 0
A47: Florida East | B47: BIRDS | C47: Tyrant Flycatchers | D47: Say's Phoebe | E47: Sayornis saya | F47: native | G47: 0 | H47: 0
A48: Florida East | B48: BIRDS | C48: Tyrant Flycatchers | D48: Black Phoebe | E48: Sayornis nigricans | F48: native | G48: 0 | H48: 0
... A60: Florida East | B60: BIRDS | C60: Wrens | D60: House Wren | E60: Troglodytes aedon | F60: native | G60: 0 | H60: 0
A61: Florida East | B61: BIRDS | C61: Gnatcatchers | D61: California Gnatcatcher | E61: Polioptila californica californica | F61: native | G61: 0 | H61: CDFW: Species of Special Concern
...

Sheet Gonzales
A1: Canyon | B1: Group | C1: Category | D1: Common Name | E1: Scientific Name | F1: Status | G1: Federal Listing Status | H1: State Listing Status | I1: iNat observation only | J1: Notes
B2: INVERTEBRATES
A3: Gonzales | B3: INVERTEBRATES | C3: Spiders | D3: Wolf spider | E3: Alopecosa kochii | F3: native | G3: 0 | H3: 0
A4: Gonzales | B4: INVERTEBRATES | C4: Ants, Bees, Wasps | D4: Argentine Ant | E4: Linepithema humile | F4: non-native | G4: 0 | H4: 0
A5: Gonzales | B5: INVERTEBRATES | C5: Spiders | D5: Ground spider | E5: Gnaphosa californica | F5: native | G5: 0 | H5: 0
A6: Gonzales | B6: INVERTEBRATES | C6: Ants, Bees, Wasps | D6: European honey bee | E6: Apis mellifera | F6: non-native | G6: 0 | H6: 0
A7: Gonzales | B7: INVERTEBRATES | C7: Spiders | D7: Wolf spider | E7: Pardosa californica | F7: native | G7: 0 | H7: 0
A8: Gonzales | B8: INVERTEBRATES | C8: Spiders | D8: Wall spider | E8: Oecobius navus | F8: non-native | G8: 0 | H8: 0
A9: Gonzales | B9: INVERTEBRATES | C9: Spiders | D9: Ground spider | E9: Marinarozelotes barbatus | F9: non-native | G9: 0 | H9: 0
A10: Gonzales | B10: INVERTEBRATES | C10: Beetles | D10: Soft-winged Flower Beetle | E10: Eschatocrepis constrictus | F10: unsure | G10: 0 | H10: 0
A11: Gonzales | B11: INVERTEBRATES | C11: Spiders | D11: Paradise spider | E11: Habronattus californicus | F11: native | G11: 0 | H11: 0
A12: Gonzales | B12: INVERTEBRATES | C12: Beetles | D12: Bark and Ambrosia Beetle | E12: Xyleborinus sp. | F12: unsure | G12: 0 | H12: 0
A13: Gonzales | B13: INVERTEBRATES | C13: Ants, Bees, Wasps | D13: Prong-faced Slender-Mason | E13: Protosmia rubifloris | F13: native | G13: 0 | H13: 0
A14: Gonzales | B14: INVERTEBRATES | C14: Spiders | D14: Woodlouse spider | E14: Dysdera crocata | F14: non-native | G14: 0 | H14: 0
... A21: Gonzales | B21: INVERTEBRATES | C21: Spiders | D21: California Trapdoor spider | E21: Bothriocyrtum californicum | F21: native | G21: 0 | H21: 0
B22: REPTILES & AMPHIBIANS
A23: Gonzales | B23: REPTILES & AMPHIBIANS | C23: Frogs | D23: Western Toad | E23: Anaxyrus boreas | F23: native | G23: 0 | H23: 0
A24: Gonzales | B24: REPTILES & AMPHIBIANS | C24: Lizards | D24: Southern California Legless Lizard | E24: Anniella stebbinsi | F24: native | G24: 0 | H24: CDFW: Species of Special Concern | I24: *
A25: Gonzales | B25: REPTILES & AMPHIBIANS | C25: Lizards | D25: Orange-throated Whiptail | E25: Aspidoscelis hyperythrus | F25: native | G25: 0 | H25: CDFW: Species of Special Concern (Watch List)
A26: Gonzales | B26: REPTILES & AMPHIBIANS | C26: Salamanders | D26: Garden Slender Salamander | E26: Batrachoseps major | F26: native | G26: 0 | H26: 0
A27: Gonzales | B27: REPTILES & AMPHIBIANS | C27: Snakes | D27: Western Rattlesnake | E27: Crotalus oreganus | F27: native | G27: 0 | H27: 0
A28: Gonzales | B28: REPTILES & AMPHIBIANS | C28: Snakes | D28: Red Diamond Rattlesnake | E28: Crotalus ruber | F28: native | G28: 0 | H28: CDFW: Species of Special Concern
A29: Gonzales | B29: REPTILES & AMPHIBIANS | C29: Snakes | D29: Ring-necked Snake | E29: Diadophis punctatus | F29: native | G29: 0 | H29: 0
A30: Gonzales | B30: REPTILES & AMPHIBIANS | C30: Lizards | D30: Southern Alligator Lizard | E30: Elgaria multicarinata | F30: native | G30: 0 | H30: 0 | J30: Camera Trap By-catch
A31: Gonzales | B31: REPTILES & AMPHIBIANS | C31: Snakes | D31: Coast Night Snake | E31: Hypsiglena ochrorhyncha | F31: native | G31: 0 | H31: 0 | I31: *
A32: Gonzales | B32: REPTILES & AMPHIBIANS | C32: Snakes | D32: California Kingsnake | E32: Lampropeltis californiae | F32: native | G32: 0 | H32: 0
A33: Gonzales | B33: REPTILES & AMPHIBIANS | C33: Frogs | D33: American Bullfrog | E33: Lithobates catesbeianus | F33: non-native | G33: 0 | H33: 0
A34: Gonzales | B34: REPTILES & AMPHIBIANS | C34: Snakes | D34: Striped Racer | E34: Masticophis lateralis | F34: native | G34: 0 | H34: 0
A35: Gonzales | B35: REPTILES & AMPHIBIANS | C35: Snakes | D35: Gophersnake | E35: Pituophis catenifer | F35: native | G35: 0 | H35: 0
A36: Gonzales | B36: REPTILES & AMPHIBIANS | C36: Lizards | D36: Western Skink | E36: Plestiodon skiltonianus | F36: native | G36: 0 | H36: CDFW: Species of Special Concern (Watch List) | I36: *
A37: Gonzales | B37: REPTILES & AMPHIBIANS | C37: Frogs | D37: Pacific Treefrog | E37: Pseudacris regilla | F37: native | G37: 0 | H37: 0
A38: Gonzales | B38: REPTILES & AMPHIBIANS | C38: Snakes | D38: Long-nosed Snake | E38: Rhinocheilus lecontei | F38: native | G38: 0 | H38: 0 | I38: *
A39: Gonzales | B39: REPTILES & AMPHIBIANS | C39: Lizards | D39: Western Fence Lizard | E39: Sceloporus occidentalis | F39: native | G39: 0 | H39: 0
A40: Gonzales | B40: REPTILES & AMPHIBIANS | C40: Snakes | D40: Two-striped Gartersnake | E40: Thamnophis hammondii | F40: native | G40: 0 | H40: CDFW: Species of Special Concern | I40: *
B41: BIRDS
A42: Gonzales | B42: BIRDS | C42: Vultures | D42: Turkey Vulture | E42: Cathartes aura | F42: native | G42: 0 | H42: 0
A43: Gonzales | B43: BIRDS | C43: Hawks & Eagles | D43: Cooper's Hawk | E43: Accipiter cooperii | F43: native | G43: 0 | H43: CDFW: Watch List
A44: Gonzales | B44: BIRDS | C44: Hawks & Eagles | D44: Red-shouldered Hawk | E44: Buteo lineatus | F44: native | G44: 0 | H44: 0
A45: Gonzales | B45: BIRDS | C45: Hawks & Eagles | D45: Red-tailed Hawk | E45: Buteo jamaicensis | F45: native | G45: 0 | H45: 0
A46: Gonzales | B46: BIRDS | C46: Falcons | D46: American Kestrel | E46: Falco sparverius | F46: native | G46: 0 | H46: 0
...

Sheet KateSessions
A1: Canyon | B1: Group | C1: Category | D1: Common Name | E1: Scientific Name | F1: Status | G1: Federal Listing Status | H1: State Listing Status | I1: iNat observation only | J1: Notes
B2: INVERTEBRATES
A3: Kate Sessions | B3: INVERTEBRATES | C3: Ants, Bees, Wasps | D3: Tripartite Sweat Bee | E3: Halictus tripartitus | F3: non-native | G3: 0 | H3: 0
A4: Kate Sessions | B4: INVERTEBRATES | C4: Ants, Bees, Wasps | D4: European honey bee | E4: Apis mellifera | F4: non-native | G4: 0 | H4: 0
A5: Kate Sessions | B5: INVERTEBRATES | C5: Beetles | D5: Soft-winged Flower Beetle | E5: Eschatocrepis constrictus | F5: unsure | G5: 0 | H5: 0
A6: Kate Sessions | B6: INVERTEBRATES | C6: Ants, Bees, Wasps | D6: Fine Striped Sweat Bee | E6: Agapostemon subtilior | F6: native | G6: 0 | H6: 0
A7: Kate Sessions | B7: INVERTEBRATES | C7: Spiders | D7: Wolf spider | E7: Alopecosa kochii | F7: native | G7: 0 | H7: 0
A8: Kate Sessions | B8: INVERTEBRATES | C8: Spiders | D8: Ground spider | E8: Drassyllus insularis | F8: native | G8: 0 | H8: 0
A9: Kate Sessions | B9: INVERTEBRATES | C9: Spiders | D9: Mesh web weavers | E9: Yorima angelica | F9: native | G9: 0 | H9: 0
A10: Kate Sessions | B10: INVERTEBRATES | C10: Spiders | D10: Wall spider | E10: Oecobius navus | F10: non-native | G10: 0 | H10: 0
A11: Kate Sessions | B11: INVERTEBRATES | C11: Ants, Bees, Wasps | D11: Argentine Ant | E11: Linepithema humile | F11: non-native | G11: 0 | H11: 0
A12: Kate Sessions | B12: INVERTEBRATES | C12: Beetles | D12: Wooly Darkling Beetle | E12: Eleodes osculans | F12: native | G12: 0 | H12: 0
A13: Kate Sessions | B13: INVERTEBRATES | C13: Spiders | D13: Jumping spider | E13: Neon avalonus | F13: native | G13: 0 | H13: 0
A14: Kate Sessions | B14: INVERTEBRATES | C14: Spiders | D14: Jumping spider | E14: Talavera minuta | F14: native | G14: 0 | H14: 0
A15: Kate Sessions | B15: INVERTEBRATES | C15: Spiders | D15: Woodlouse spider | E15: Dysdera crocata | F15: non-native | G15: 0 | H15: 0
B16: REPTILES & AMPHIBIANS | D16: * denotes iNat observation only
A17: Kate Sessions | B17: REPTILES & AMPHIBIANS | C17: Lizards | D17: Orange-throated Whiptail | E17: Aspidoscelis hyperythrus | F17: native | G17: 0 | H17: CDFW: Species of Special Concern (Watch List)
A18: Kate Sessions | B18: REPTILES & AMPHIBIANS | C18: Salamanders | D18: Garden Slender Salamander | E18: Batrachoseps major | F18: native | G18: 0 | H18: 0
A19: Kate Sessions | B19: REPTILES & AMPHIBIANS | C19: Snakes | D19: Western Rattlesnake | E19: Crotalus oreganus | F19: native | G19: 0 | H19: 0
A20: Kate Sessions | B20: REPTILES & AMPHIBIANS | C20: Snakes | D20: California Kingsnake | E20: Lampropeltis californiae | F20: native | G20: 0 | H20: 0
A21: Kate Sessions | B21: REPTILES & AMPHIBIANS | C21: Lizards | D21: Western Skink | E21: Plestiodon skiltonianus | F21: native | G21: 0 | H21: CDFW: Species of Special Concern (Watch List)
A22: Kate Sessions | B22: REPTILES & AMPHIBIANS | C22: Snakes | D22: Gophersnake | E22: Pituophis catenifer | F22: native | G22: 0 | H22: 0 | I22: *
A23: Kate Sessions | B23: REPTILES & AMPHIBIANS | C23: Lizards | D23: Western Fence Lizard | E23: Sceloporus occidentalis | F23: native | G23: 0 | H23: 0
A24: Kate Sessions | B24: REPTILES & AMPHIBIANS | C24: Lizards | D24: Common Side-blotched Lizard | E24: Uta stansburiana | F24: native | G24: 0 | H24: 0
B25: BIRDS
A26: Kate Sessions | B26: BIRDS | C26: Hawks & Eagles | D26: Cooper's Hawk | E26: Accipiter cooperii | F26: native | G26: 0 | H26: CDFW: Watch List
A27: Kate Sessions | B27: BIRDS | C27: Hawks & Eagles | D27: Red-shouldered Hawk | E27: Buteo lineatus | F27: native | G27: 0 | H27: 0
A28: Kate Sessions | B28: BIRDS | C28: Pigeons & Doves | D28: Mourning Dove | E28: Zenaida macroura | F28: native | G28: 0 | H28: 0
A29: Kate Sessions | B29: BIRDS | C29: Parrot | D29: Red-masked Parakeet | E29: Aratinga erythrogenys | F29: non-native | G29: 0 | H29: 0
A30: Kate Sessions | B30: BIRDS | C30: Hummingbirds | D30: Anna's Hummingbird | E30: Calypte anna | F30: native | G30: 0 | H30: 0
A31: Kate Sessions | B31: BIRDS | C31: Hummingbirds | D31: Allen's Hummingbird | E31: Selasphorus sasin | F31: native | G31: 0 | H31: 0
A32: Kate Sessions | B32: BIRDS | C32: Woodpeckers | D32: Nuttall's Woodpecker | E32: Dryobates nuttallii | F32: native | G32: 0 | H32: 0
A33: Kate Sessions | B33: BIRDS | C33: Tyrant Flycatchers | D33: Say's Phoebe | E33: Sayornis saya | F33: native | G33: 0 | H33: 0
A34: Kate Sessions | B34: BIRDS | C34: Tyrant Flycatchers | D34: Black Phoebe | E34: Sayornis nigricans | F34: native | G34: 0 | H34: 0
A35: Kate Sessions | B35: BIRDS | C35: Tyrant Flycatchers | D35: Cassin's Kingbird | E35: Tyrannus vociferans | F35: native | G35: 0 | H35: 0
A36: Kate Sessions | B36: BIRDS | C36: Crows & Jays | D36: California Scrub Jay | E36: Aphelocoma californica | F36: native | G36: 0 | H36: 0
A37: Kate Sessions | B37: BIRDS | C37: Crows & Jays | D37: American Crow | E37: Corvus brachyrhynchos | F37: native | G37: 0 | H37: 0
A38: Kate Sessions | B38: BIRDS | C38: Thrushes | D38: Hermit Thrush | E38: Catharus guttatus | F38: native | G38: 0 | H38: 0
... A41: Kate Sessions | B41: BIRDS | C41: Wrens | D41: Bewick's Wren | E41: Thryomanes bewickii | F41: native | G41: 0 | H41: 0
A42: Kate Sessions | B42: BIRDS | C42: Gnatcatchers | D42: California Gnatcatcher | E42: Polioptila californica californica | F42: native | G42: Federally Threatened | H42: CDFW: Species of Special Concern
...

Sheet LaJollaHeights
A1: Canyon | B1: Group | C1: Category | D1: Common Name | E1: Scientific Name | F1: Status | G1: Federal Listing Status | H1: State Listing Status | I1: iNat observation only
B2: INVERTEBRATES
A3: La Jolla Heights | B3: INVERTEBRATES | C3: Ants, Bees, Wasps | D3: Argentine Ant | E3: Linepithema humile | F3: non-native | G3: 0 | H3: 0
A4: La Jolla Heights | B4: INVERTEBRATES | C4: Spiders | D4: Wall spider | E4: Oecobius navus | F4: non-native | G4: 0 | H4: 0
A5: La Jolla Heights | B5: INVERTEBRATES | C5: Spiders | D5: Ground sac spider | E5: Meriola californica | F5: native | G5: 0 | H5: 0
A6: La Jolla Heights | B6: INVERTEBRATES | C6: Ants, Bees, Wasps | D6: European honey bee | E6: Apis mellifera | F6: non-native | G6: 0 | H6: 0
A7: La Jolla Heights | B7: INVERTEBRATES | C7: Ants, Bees, Wasps | D7: Tripartite Sweat Bee | E7: Halictus tripartitus | F7: non-native | G7: 0 | H7: 0
A8: La Jolla Heights | B8: INVERTEBRATES | C8: Spiders | D8: Ground spider | E8: Drassyllus insularis | F8: native | G8: 0 | H8: 0
A9: La Jolla Heights | B9: INVERTEBRATES | C9: Beetles | D9: Little Bear | E9: Paracotalpa ursina | F9: unsure | G9: 0 | H9: 0
B10: REPTILES & AMPHIBIANS | D10: * denotes iNat observation only
A11: La Jolla Heights | B11: REPTILES & AMPHIBIANS | C11: Salamanders | D11: Garden Slender Salamander | E11: Batrachoseps major | F11: native | G11: 0 | H11: 0
A12: La Jolla Heights | B12: REPTILES & AMPHIBIANS | C12: Lizards | D12: Southern Alligator Lizard | E12: Elgaria multicarinata | F12: native | G12: 0 | H12: 0
A13: La Jolla Heights | B13: REPTILES & AMPHIBIANS | C13: Lizards | D13: Western Skink | E13: Plestiodon skiltonianus | F13: native | G13: 0 | H13: CDFW: Species of Special Concern (Watch List)
A14: La Jolla Heights | B14: REPTILES & AMPHIBIANS | C14: Lizards | D14: Western Fence Lizard | E14: Sceloporus occidentalis | F14: native | G14: 0 | H14: 0
B15: BIRDS
A16: La Jolla Heights | B16: BIRDS | C16: Hawks & Eagles | D16: Cooper's Hawk | E16: Accipiter cooperii | F16: native | G16: 0 | H16: CDFW: Watch List
A17: La Jolla Heights | B17: BIRDS | C17: Hawks & Eagles | D17: Red-shouldered Hawk | E17: Buteo lineatus | F17: native | G17: 0 | H17: 0
A18: La Jolla Heights | B18: BIRDS | C18: Gulls & Terns | D18: Western Gull | E18: Larus occidentalis | F18: native | G18: 0 | H18: 0
A19: La Jolla Heights | B19: BIRDS | C19: Pigeons & Doves | D19: Mourning Dove | E19: Zenaida macroura | F19: native | G19: 0 | H19: 0
A20: La Jolla Heights | B20: BIRDS | C20: Parrot | D20: Red-masked Parakeet | E20: Aratinga erythrogenys | F20: non-native | G20: 0 | H20: 0
A21: La Jolla Heights | B21: BIRDS | C21: Hummingbirds | D21: Anna's Hummingbird | E21: Calypte anna | F21: native | G21: 0 | H21: 0
A22: La Jolla Heights | B22: BIRDS | C22: Hummingbirds | D22: Allen's Hummingbird | E22: Selasphorus sasin | F22: native | G22: 0 | H22: 0
A23: La Jolla Heights | B23: BIRDS | C23: Woodpeckers | D23: Nuttall's Woodpecker | E23: Dryobates nuttallii | F23: native | G23: 0 | H23: 0
A24: La Jolla Heights | B24: BIRDS | C24: Tyrant Flycatchers | D24: Western Flycatcher | E24: Empidonax difficilis | F24: native | G24: 0 | H24: 0
A25: La Jolla Heights | B25: BIRDS | C25: Tyrant Flycatchers | D25: Black Phoebe | E25: Sayornis nigricans | F25: native | G25: 0 | H25: 0
A26: La Jolla Heights | B26: BIRDS | C26: Tyrant Flycatchers | D26: Cassin's Kingbird | E26: Tyrannus vociferans | F26: native | G26: 0 | H26: 0
A27: La Jolla Heights | B27: BIRDS | C27: Crows & Jays | D27: California Scrub Jay | E27: Aphelocoma californica | F27: native | G27: 0 | H27: 0
A28: La Jolla Heights | B28: BIRDS | C28: Crows & Jays | D28: American Crow | E28: Corvus brachyrhynchos | F28: native | G28: 0 | H28: 0
... A50: La Jolla Heights | B50: BIRDS | C50: New World Blackbirds & Orioles | D50: Hooded Oriole | E50: Icterus cucullatus | F50: native | G50: 0 | H50: 0
B51: MAMMALS
A52: La Jolla Heights | B52: MAMMALS | C52: Rodents | D52: Big-eared Woodrat | E52: Neotoma macrotis | F52: native | G52: 0 | H52: 0
A53: La Jolla Heights | B53: MAMMALS | C53: Rodents | D53: California Mouse | E53: Peromyscus californicus | F53: native | G53: 0 | H53: 0
A54: La Jolla Heights | B54: MAMMALS | C54: Rodents | D54: North American Deer Mouse | E54: Peromyscus maniculatus | F54: native | G54: 0 | H54: 0
A55: La Jolla Heights | B55: MAMMALS | C55: Rodents | D55: Western Harvest Mouse | E55: Reithrodontomys megalotis | F55: native | G55: 0 | H55: 0
A56: La Jolla Heights | B56: MAMMALS | C56: Carnivores | D56: Coyote | E56: Canis latrans | F56: native | G56: 0 | H56: 0
A57: La Jolla Heights | B57: MAMMALS | C57: Carnivores | D57: Bobcat | E57: Lynx rufus | F57: native | G57: 0 | H57: 0
A58: La Jolla Heights | B58: MAMMALS | C58: Carnivores | D58: Striped Skunk | E58: Mephitis mephitis | F58: native | G58: 0 | H58: 0
A59: La Jolla Heights | B59: MAMMALS | C59: Bats | D59: Mexican Free-tailed Bat | E59: Tadarida brasiliensis | F59: native | G59: 0 | H59: 0
A60: La Jolla Heights | B60: MAMMALS | C60: Bats | D60: Western Red Bat | E60: Lasiurus frantzii | F60: native | G60: 0 | H60: CDFW: Species of Special Concern
A61: La Jolla Heights | B61: MAMMALS | C61: Bats | D61: Yuma Myotis | E61: Myotis yumanensis | F61: native | G61: 0 | H61: 0
...

Sheet Los Penasquitos_DelMarMesa
A1: Canyon | B1: Group | C1: Category | D1: Common Name | E1: Scientific Name | F1: Status | G1: Federal Listing Status | H1: State Listing Status | I1: iNat observation only | J1: Notes
B2: INVERTEBRATES
A3: Los Peñasquitos/Del Mar Mesa | B3: INVERTEBRATES | C3: =_xlfn.XLOOKUP(E3,KEY!C:C,KEY!A:A,FALSE) -> Ants, Bees, Wasps | D3: Argentine Ant | E3: Linepithema humile | F3: non-native | G3: 0 | H3: 0
A4: Los Peñasquitos/Del Mar Mesa | B4: INVERTEBRATES | C4: =_xlfn.XLOOKUP(E4,KEY!C:C,KEY!A:A,FALSE) -> Spiders | D4: Ghost spider | E4: Lupettiana mordax | F4: native | G4: 0 | H4: 0
A5: Los Peñasquitos/Del Mar Mesa | B5: INVERTEBRATES | C5: =_xlfn.XLOOKUP(E5,KEY!C:C,KEY!A:A,FALSE) -> Ants, Bees, Wasps | D5: European honey bee | E5: Apis mellifera | F5: non-native | G5: 0 | H5: 0
A6: Los Peñasquitos/Del Mar Mesa | B6: INVERTEBRATES | C6: =_xlfn.XLOOKUP(E6,KEY!C:C,KEY!A:A,FALSE) -> Spiders | D6: Ground spider | E6: Zelotes gynethus | F6: native | G6: 0 | H6: 0
A7: Los Peñasquitos/Del Mar Mesa | B7: INVERTEBRATES | C7: =_xlfn.XLOOKUP(E7,KEY!C:C,KEY!A:A,FALSE) -> Beetles | D7: Dentate Stink Beetle | E7: Eleodes dentipes | F7: native | G7: 0 | H7: 0
A8: Los Peñasquitos/Del Mar Mesa | B8: INVERTEBRATES | C8: =_xlfn.XLOOKUP(E8,KEY!C:C,KEY!A:A,FALSE) -> Spiders | D8: Ground spider | E8: Drassyllus insularis | F8: native | G8: 0 | H8: 0
A9: Los Peñasquitos/Del Mar Mesa | B9: INVERTEBRATES | C9: =_xlfn.XLOOKUP(E9,KEY!C:C,KEY!A:A,FALSE) -> Spiders | D9: Crab spider | E9: Xysticus californicus | F9: native | G9: 0 | H9: 0
A10: Los Peñasquitos/Del Mar Mesa | B10: INVERTEBRATES | C10: =_xlfn.XLOOKUP(E10,KEY!C:C,KEY!A:A,FALSE) -> Spiders | D10: Wall spider | E10: Oecobius navus | F10: non-native | G10: 0 | H10: 0
A11: Los Peñasquitos/Del Mar Mesa | B11: INVERTEBRATES | C11: =_xlfn.XLOOKUP(E11,KEY!C:C,KEY!A:A,FALSE) -> Spiders | D11: Red-backed jumping spider | E11: Phidippus johnsoni | F11: native | G11: 0 | H11: 0
A12: Los Peñasquitos/Del Mar Mesa | B12: INVERTEBRATES | C12: =_xlfn.XLOOKUP(E12,KEY!C:C,KEY!A:A,FALSE) -> Beetles | D12: Soft-winged Flower Beetle | E12: Eschatocrepis constrictus | F12: unsure | G12: 0 | H12: 0
A13: Los Peñasquitos/Del Mar Mesa | B13: INVERTEBRATES | C13: =_xlfn.XLOOKUP(E13,KEY!C:C,KEY!A:A,FALSE) -> Spiders | D13: Sheet weaver spider | E13: "Agyneta" #2 | F13: native | G13: 0 | H13: 0
A14: Los Peñasquitos/Del Mar Mesa | B14: INVERTEBRATES | C14: =_xlfn.XLOOKUP(E14,KEY!C:C,KEY!A:A,FALSE) -> Spiders | D14: Prowling spider | E14: Syspira tigrina | F14: native | G14: 0 | H14: 0
A15: Los Peñasquitos/Del Mar Mesa | B15: INVERTEBRATES | C15: =_xlfn.XLOOKUP(E15,KEY!C:C,KEY!A:A,FALSE) -> Spiders | D15: Ant mimic spider | E15: Castianeira thalia | F15: native | G15: 0 | H15: 0
A16: * denotes iNat observation only | B16: REPTILES & AMPHIBIANS
A17: Los Peñasquitos/Del Mar Mesa | B17: REPTILES & AMPHIBIANS | C17: =_xlfn.XLOOKUP(E17,KEY!C:C,KEY!A:A,FALSE) -> Frogs | D17: Western Toad | E17: Anaxyrus boreas | F17: native | G17: 0 | H17: 0
A18: Los Peñasquitos/Del Mar Mesa | B18: REPTILES & AMPHIBIANS | C18: =_xlfn.XLOOKUP(E18,KEY!C:C,KEY!A:A,FALSE) -> Salamanders | D18: Arboreal Salamander | E18: Aneides lugubris | F18: native | G18: 0 | H18: 0 | I18: *
A19: Los Peñasquitos/Del Mar Mesa | B19: REPTILES & AMPHIBIANS | C19: =_xlfn.XLOOKUP(E19,KEY!C:C,KEY!A:A,FALSE) -> Lizards | D19: Orange-throated Whiptail | E19: Aspidoscelis hyperythrus | F19: native | G19: 0 | H19: CDFW: Species of Special Concern (Watch List)
A20: Los Peñasquitos/Del Mar Mesa | B20: REPTILES & AMPHIBIANS | C20: Lizards | D20: Tiger Whiptail | E20: Aspidoscelis tigris | F20: native | G20: 0 | H20: CDFW: Species of Special Concern
A21: Los Peñasquitos/Del Mar Mesa | B21: REPTILES & AMPHIBIANS | C21: =_xlfn.XLOOKUP(E21,KEY!C:C,KEY!A:A,FALSE) -> Salamanders | D21: Garden Slender Salamander | E21: Batrachoseps major | F21: native | G21: 0 | H21: 0 | I21: *
A22: Los Peñasquitos/Del Mar Mesa | B22: REPTILES & AMPHIBIANS | C22: =_xlfn.XLOOKUP(E22,KEY!C:C,KEY!A:A,FALSE) -> Snakes | D22: North American Racer | E22: Coluber constrictor | F22: native | G22: 0 | H22: 0
A23: Los Peñasquitos/Del Mar Mesa | B23: REPTILES & AMPHIBIANS | C23: =_xlfn.XLOOKUP(E23,KEY!C:C,KEY!A:A,FALSE) -> Snakes | D23: Western Rattlesnake | E23: Crotalus oreganus | F23: native | G23: 0 | H23: 0
A24: Los Peñasquitos/Del Mar Mesa | B24: REPTILES & AMPHIBIANS | C24: Snakes | D24: Red Diamond Rattlesnake | E24: Crotalus ruber | F24: native | G24: 0 | H24: CDFW: Species of Special Concern | I24: *
A25: Los Peñasquitos/Del Mar Mesa | B25: REPTILES & AMPHIBIANS | C25: =_xlfn.XLOOKUP(E25,KEY!C:C,KEY!A:A,FALSE) -> Lizards | D25: Southern Alligator Lizard | E25: Elgaria multicarinata | F25: native | G25: 0 | H25: 0
A26: Los Peñasquitos/Del Mar Mesa | B26: REPTILES & AMPHIBIANS | C26: Snakes | D26: Coast Night Snake | E26: Hypsiglena ochrorhyncha | F26: native | G26: 0 | H26: 0 | I26: *
A27: Los Peñasquitos/Del Mar Mesa | B27: REPTILES & AMPHIBIANS | C27: Snakes | D27: California Kingsnake | E27: Lampropeltis californiae | F27: native | G27: 0 | H27: 0 | I27: *
A28: Los Peñasquitos/Del Mar Mesa | B28: REPTILES & AMPHIBIANS | C28: =_xlfn.XLOOKUP(E28,KEY!C:C,KEY!A:A,FALSE) -> Frogs | D28: American Bullfrog | E28: Lithobates catesbeianus | F28: non-native | G28: 0 | H28: 0 | I28: *
A29: Los Peñasquitos/Del Mar Mesa | B29: REPTILES & AMPHIBIANS | C29: Snakes | D29: Gophersnake | E29: Pituophis catenifer | F29: native | G29: 0 | H29: 0 | I29: *
A30: Los Peñasquitos/Del Mar Mesa | B30: REPTILES & AMPHIBIANS | C30: Snakes | D30: Striped Racer | E30: Masticophis lateralis | F30: native | G30: 0 | H30: 0 | I30: *
A31: Los Peñasquitos/Del Mar Mesa | B31: REPTILES & AMPHIBIANS | C31: =_xlfn.XLOOKUP(E31,KEY!C:C,KEY!A:A,FALSE) -> Lizards | D31: Western Skink | E31: Plestiodon skiltonianus | F31: native | G31: 0 | H31: CDFW: Species of Special Concern (Watch List)
A32: Los Peñasquitos/Del Mar Mesa | B32: REPTILES & AMPHIBIANS | C32: =_xlfn.XLOOKUP(E32,KEY!C:C,KEY!A:A,FALSE) -> Frogs | D32: Pacific Treefrog | E32: Pseudacris regilla | F32: native | G32: 0 | H32: 0
A33: Los Peñasquitos/Del Mar Mesa | B33: REPTILES & AMPHIBIANS | C33: =_xlfn.XLOOKUP(E33,KEY!C:C,KEY!A:A,FALSE) -> Lizards | D33: Blainville's Horned Lizard | E33: Phrynosoma blainvillii | F33: native | G33: 0 | H33: CDFW: Species of Special Concern | I33: *
A34: Los Peñasquitos/Del Mar Mesa | B34: REPTILES & AMPHIBIANS | C34: =_xlfn.XLOOKUP(E34,KEY!C:C,KEY!A:A,FALSE) -> Lizards | D34: Western Fence Lizard | E34: Sceloporus occidentalis | F34: native | G34: 0 | H34: 0
A35: Los Peñasquitos/Del Mar Mesa | B35: REPTILES & AMPHIBIANS | C35: Frogs | D35: Western Spadefoot | E35: Spea hammondii | F35: native | G35: 0 | H35: CDFW: Species of Special Concern | I35: * | J35: coordinates obscurred
A36: Los Peñasquitos/Del Mar Mesa | B36: REPTILES & AMPHIBIANS | C36: =_xlfn.XLOOKUP(E36,KEY!C:C,KEY!A:A,FALSE) -> Snakes | D36: Two-striped Gartersnake | E36: Thamnophis hammondii | F36: native | G36: 0 | H36: CDFW: Species of Special Concern | I36: *
A37: Los Peñasquitos/Del Mar Mesa | B37: REPTILES & AMPHIBIANS | C37: Turtles | D37: Slider | E37: Trachemys scripta | F37: non-native | G37: 0 | H37: 0
A38: Los Peñasquitos/Del Mar Mesa | B38: REPTILES & AMPHIBIANS | C38: =_xlfn.XLOOKUP(E38,KEY!C:C,KEY!A:A,FALSE) -> Frogs | D38: African Clawed Frog | E38: Xenopus laevis | F38: non-native | G38: 0 | H38: 0 | I38: *
B39: BIRDS
A40: Los Peñasquitos/Del Mar Mesa | B40: BIRDS | C40: =_xlfn.XLOOKUP(E40,KEY!C:C,KEY!A:A,FALSE) -> Hawks & Eagles | D40: Cooper's Hawk | E40: Accipiter cooperii | F40: native | G40: 0 | H40: CDFW: Watch List
...

Sheet Manzanita
A1: NO DATA FOR MANZANITA

Sheet MissionHills
A1: Canyon | B1: Group | C1: Category | D1: Common Name | E1: Scientific Name | F1: Status | G1: Federal Listing Status | H1: State Listing Status | I1: iNat observation only
B2: INVERTEBRATES
A3: Misson Hills/Washington | B3: INVERTEBRATES | C3: Spiders | D3: Ground spider | E3: Zelotes gynethus | F3: native | G3: 0 | H3: 0
A4: Misson Hills/Washington | B4: INVERTEBRATES | C4: Ants, Bees, Wasps | D4: Argentine Ant | E4: Linepithema humile | F4: non-native | G4: 0 | H4: 0
A5: Misson Hills/Washington | B5: INVERTEBRATES | C5: Spiders | D5: Woodlouse spider | E5: Dysdera crocata | F5: non-native | G5: 0 | H5: 0
A6: Misson Hills/Washington | B6: INVERTEBRATES | C6: Ants, Bees, Wasps | D6: European honey bee | E6: Apis mellifera | F6: non-native | G6: 0 | H6: 0
A7: Misson Hills/Washington | B7: INVERTEBRATES | C7: Spiders | D7: Goblin spider | E7: Opopaea concolor | F7: non-native | G7: 0 | H7: 0
A8: Misson Hills/Washington | B8: INVERTEBRATES | C8: Spiders | D8: Ground sac spider | E8: Meriola californica | F8: native | G8: 0 | H8: 0
A9: Misson Hills/Washington | B9: INVERTEBRATES | C9: Spiders | D9: Wolf spider | E9: Alopecosa kochii | F9: native | G9: 0 | H9: 0
A10: Misson Hills/Washington | B10: INVERTEBRATES | C10: Spiders | D10: Wall spider | E10: Oecobius navus | F10: non-native | G10: 0 | H10: 0
A11: Misson Hills/Washington | B11: INVERTEBRATES | C11: Spiders | D11: Wolf spider | E11: Pardosa californica | F11: native | G11: 0 | H11: 0
A12: Misson Hills/Washington | B12: INVERTEBRATES | C12: Spiders | D12: Mesh web weavers | E12: Yorima angelica | F12: native | G12: 0 | H12: 0
A13: Misson Hills/Washington | B13: INVERTEBRATES | C13: Spiders | D13: Ground spider | E13: Drassyllus insularis | F13: native | G13: 0 | H13: 0
B14: RETILES & AMPHIBIANS | D14: * denotes iNat observation only
A15: Misson Hills/Washington | B15: RETILES & AMPHIBIANS | C15: Snakes | D15: Western Rattlesnake | E15: Crotalus oreganus | F15: native | G15: 0 | H15: 0 | I15: *
A16: Misson Hills/Washington | B16: RETILES & AMPHIBIANS | C16: Snakes | D16: Striped Racer | E16: Masticophis lateralis | F16: native | G16: 0 | H16: 0
A17: Misson Hills/Washington | B17: RETILES & AMPHIBIANS | C17: Lizards | D17: Southern Alligator Lizard | E17: Elgaria multicarinata | F17: native | G17: 0 | H17: 0
A18: Misson Hills/Washington | B18: RETILES & AMPHIBIANS | C18: Lizards | D18: Western Skink | E18: Plestiodon skiltonianus | F18: native | G18: 0 | H18: CDFW: Species of Special Concern (Watch List)
A19: Misson Hills/Washington | B19: RETILES & AMPHIBIANS | C19: Lizards | D19: Western Fence Lizard | E19: Sceloporus occidentalis | F19: native | G19: 0 | H19: 0
B20: BIRDS
A21: Misson Hills/Washington | B21: BIRDS | C21: Herons & Bitterns | D21: Great Blue Heron | E21: Ardea herodias | F21: native | G21: 0 | H21: CDF: S
A22: Misson Hills/Washington | B22: BIRDS | C22: Hawks & Eagles | D22: Cooper's Hawk | E22: Accipiter cooperii | F22: native | G22: 0 | H22: CDFW: Watch List
A23: Misson Hills/Washington | B23: BIRDS | C23: Hawks & Eagles | D23: Red-shouldered Hawk | E23: Buteo lineatus | F23: native | G23: 0 | H23: 0
A24: Misson Hills/Washington | B24: BIRDS | C24: Hawks & Eagles | D24: Red-tailed Hawk | E24: Buteo jamaicensis | F24: native | G24: 0 | H24: 0
A25: Misson Hills/Washington | B25: BIRDS | C25: Falcons | D25: Peregrine Falcon | E25: Falco peregrinus | F25: native | G25: 0 | H25: 0
A26: Misson Hills/Washington | B26: BIRDS | C26: Gulls & Terns | D26: Western Gull | E26: Larus occidentalis | F26: native | G26: 0 | H26: 0
A27: Misson Hills/Washington | B27: BIRDS | C27: Pigeons & Doves | D27: Mourning Dove | E27: Zenaida macroura | F27: native | G27: 0 | H27: 0
A28: Misson Hills/Washington | B28: BIRDS | C28: Parrot | D28: Red-masked Parakeet | E28: Aratinga erythrogenys | F28: non-native | G28: 0 | H28: 0
A29: Misson Hills/Washington | B29: BIRDS | C29: Hummingbirds | D29: Anna's Hummingbird | E29: Calypte anna | F29: native | G29: 0 | H29: 0
A30: Misson Hills/Washington | B30: BIRDS | C30: Hummingbirds | D30: Allen's Hummingbird | E30: Selasphorus sasin | F30: native | G30: 0 | H30: 0
A31: Misson Hills/Washington | B31: BIRDS | C31: Woodpeckers | D31: Nuttall's Woodpecker | E31: Dryobates nuttallii | F31: native | G31: 0 | H31: 0
A32: Misson Hills/Washington | B32: BIRDS | C32: Tyrant Flycatchers | D32: Western Flycatcher | E32: Empidonax difficilis | F32: native | G32: 0 | H32: 0
A33: Misson Hills/Washington | B33: BIRDS | C33: Tyrant Flycatchers | D33: Black Phoebe | E33: Sayornis nigricans | F33: native | G33: 0 | H33: 0
A34: Misson Hills/Washington | B34: BIRDS | C34: Tyrant Flycatchers | D34: Ash-throated Flycatcher | E34: Myiarchus cinerascens | F34: native | G34: 0 | H34: 0
... A63: Misson Hills/Washington | B63: BIRDS | C63: New World Blackbirds & Orioles | D63: Hooded Oriole | E63: Icterus cucullatus | F63: native | G63: 0 | H63: 0
B64: MAMMALS
A65: Misson Hills/Washington | B65: MAMMALS | C65: Rodents | D65: House Mouse | E65: Mus musculus | F65: non-native | G65: 0 | H65: 0
